Workbook

Sheet Monitoramento Geral
A1: PROCESSO | B1: CADASTRADO DF | C1: DESPACHO | D1: NOTIFICAÇÃO | E1: RECEBIMENTO AR | F1: RESPOSTA | G1: 2 NOTIFICAÇÃO | H1: RECEBIMENTO AR 2 NOT | I1: Desc. Folha | J1: valor 2 trimestre | K1: 2 trimestre 2025 | L1: ESTADUAL / MUNICIPAL | M1: ÓRGÃO | N1: PROCESSO SEI OU OUTROS | O1: TRASNF. FRAP | P1: PAGO SITE TCE | Q1: TIPO PAGAMENTO | R1: REMANESCENTE | S1: APR | T1: VALOR ORIGINAL | U1: NOME | V1: CPF | W1: OBSERVAÇÕES
A2: 004772/2024 | C2: 45727 | D2: 45728 | E2: 45740 | G2: 45824 | H2: 45838 | L2: Estadual | M2: IPERN | T2: 19659.84 | U2: ADOLFO JOSÉ DA SILVEIRA NETO | V2: 818758430
A3: 000852/2025 | C3: 45784 | D3: 45790 | E3: 45792 | F3: 45804 | L3: Municipal | M3: URBANA - COMPANHIA DE SERVIÇOS URBANOS DE NATAL | T3: 3000 | U3: Alexandre Magno de Montenegro Miranda | V3: 15726916468 | W3: Alexandre Magno de Montenegro Miranda não faz mais parte do quadro de funcionários da URBANA
A4: 003368/2024 | B4: SIM | C4: 45784 | D4: 45790 | E4: 45803 | F4: 45839 | G4: 46035 | H4: 46073 | I4: sim | L4: Municipal | M4: Câmara Municipal de Pendências | T4: 11589.27 | U4: Alexandre Pereira de Araujo Montenegro | V4: 7227091457 | W4: Parcelamento cancelado
A5: 002058/2024 | C5: 45622 | D5: 45625 | E5: 45635 | G5: 45918 | H5: 45938 | L5: Municipal | M5: PREFEITURA MUNICIPAL DE SERRA DO MEL | P5: 45965 | Q5: parcelado | T5: 5000 | U5: ANAXIMANDRO RODRIGUES DO VALE COSTA | V5: 96965223472 | W5: Parcelamento cancelado
A6: 000070/2025 | B6: SIM | C6: 45684 | D6: 45694 | E6: 45714 | G6: 45911 | H6: 45932 | I6: sim | L6: Municipal | M6: Prefeitura Municipal de Messias Targino | T6: 3000 | U6: anderson medeiros martins | V6: 1179288440
A7: 000415/2024 | B7: SIM | C7: 45625 | D7: 45635 | E7: 45652 | F7: 45693 | I7: sim | L7: Municipal | M7: IPSS - Inst. Prev. SOCIAL Dos Serv Mun. de Olho Dagua Dos Borges | O7: 45684 | T7: 5000 | U7: Anderson Muller Holanda Cortez | V7: 8984449423 | W7: Pagou primeira parcela no site do TCE. Implementou desconto em folha segunda parcela. Juntou comprovante pagamento. PRECISAMOS MONITORAR IS RESTANTS DAS PARCELAS, COMO?
A8: 004917/2024 | C8: 45636 | L8: Municipal | M8: Prefeitura Municipal de Santa Cruz | P8: 45656 | Q8: integral | T8: 5000 | U8: Ângelo Giusepe Fonseca da Silveira | V8: 33677395453
A9: 003379/2024 | C9: 45671 | D9: 45694 | E9: 45707 | G9: 45810 | H9: 45825 | I9: sim | J9: 6592.99 | K9: sim | L9: Municipal | M9: PREFEITURA MUN. DE SÃO JOÃO DO SABUGI | O9: 45838 | Q9: Integral | R9: cancelado | T9: 5897.95 | U9: ANÍBAL PEREIRA DE ARAÚJO | V9: 15055825472
A10: 004867/2024 | B10: SIM | C10: 45727 | D10: 45727 | E10: 45748 | F10: 46063 | I10: sim | L10: Municipal | M10: PREFEITURA MUNICIPAL DE PARAÚ/RN | T10: 5000 | U10: Antônio Carlos Peixoto Nunes | V10: 789686406
A11: 004886/2024 | C11: 45727 | D11: 45728 | E11: 45740 | L11: Estadual | M11: IPERN | T11: 5632.35 | U11: ANTÔNIO MARCOS DE ABREU PEIXOTO | V11: 39356418420
A12: 000414/2024 | C12: 45615 | D12: 45625 | E12: 45637 | G12: 45792 | H12: 45813 | L12: Municipal | M12: CÂMARA MUNICIPAL DE UMARIZAL | T12: 3000 | U12: ANTONIO ROBERIO DANTAS DELFINO (VEREADOR) | V12: 48941344468 | W12: Após osegunda noticicação, advogado entrou com pedido de parcelamento em 13/06
A13: 000447/2024 | C13: 45614 | D13: 45622 | E13: 45632 | L13: Municipal | M13: PREFEITURA MUNICIPAL DE TAIPU | S13: SIM | T13: 9829.92 | U13: Ariosvaldo Bandeira Junior | V13: 12204650463 | W13: Abrir APR e seguir com a execução por outros meios
A14: 004887/2024 | C14: 45784 | D14: 45790 | E14: 45800 | L14: Municipal | M14: PREFEITURA MUNICIPAL DE NATAL | P14: 45810 | Q14: parcelado | U14: BRENNO OLIVEIRA QUEIROGA DE MORAIS | V14: 925018422
A15: 004888/2024 | C15: 45727 | D15: 45728 | E15: 45748 | L15: Municipal | M15: Câmara Municipal de Pedro Avelino | T15: 2400 | U15: Brunno Érico Teodoro Ferreira | V15: 6822161430
A16: 000481/2024 | C16: 45622 | D16: 45625 | E16: 45638 | G16: 45918 | H16: 45937 | L16: Municipal | M16: PREFEITURA MUNICIPAL DE LUÍS GOMES/RN | Q16: integral | T16: 3300 | U16: CARLOS AUGUSTO DE PAIVA (ATUAL PREFEITO) | V16: 76168883487 | W16: Abrir APR e seguir com a execução por outros meios
A17: 004871/2024 | C17: 45784 | D17: 45790 | E17: 45806 | L17: Municipal | M17: PREFEITURA MUNICIPAL DE MAJOR SALES | T17: 32170.56 | U17: CARLOS JOSÉ FERNANDES | V17: 76816591453
A18: 011032/2016 | C18: 45784 | D18: 45790 | E18: 45806 | L18: Municipal | M18: PREFEITURA MUNICIPAL DE MAJOR SALES | T18: 100 | U18: CARLOS JOSÉ FERNANDES | V18: 76816591453
A19: 001459/2023 | B19: SIM | C19: 45615 | D19: 45622 | E19: 45632 | G19: 45799 | H19: 45820 | I19: sim | L19: Municipal | M19: PREFEITURA MUNICIPAL DE PEDRA PRETA | T19: 17181.46 | U19: CARMEM JUCIENE CAMARA DA LUZ | V19: 76217663449
A20: 000724/2025 | C20: 45849 | D20: 45856 | E20: 45873 | L20: Municipal | M20: SERVIÇO AUTÔNOMO DE ÁGUA E ESGOTOS DE MAXARANGUAPE | T20: 30000 | U20: Charles de Souto Bezerra | V20: 964198495
A21: 004904/2024 | B21: SIM | C21: 45846 | D21: 45856 | E21: 45867 | F21: 45908 | I21: sim | L21: Estadual | M21: ITEP | T21: 1100 | U21: Cícero Sabino Neto | V21: 6975973423
A22: 000403/2025 | B22: SIM | C22: 45804 | D22: 45810 | E22: 45821 | F22: 45868 | I22: sim | L22: Municipal | M22: PREFEITURA MUNICIPAL DE PILÕES | O22: sim | Q22: integral | R22: Remanescente cancelado | T22: 1100 | U22: Cícero Sabino Neto | V22: 6975973423
A23: 001480/2025 | B23: SIM | C23: 45846 | D23: 45856 | E23: 45867 | F23: 45943 | I23: sim | L23: Estadual | M23: ITEP | O23: sim | T23: 1100 | U23: Cícero Sabino Neto | V23: 6975973423 | W23: DF visto no SIAI DP e na informação do ITEP no processo 004904/2024
A24: 000732/2025 | C24: 45821 | D24: 45826 | E24: 45854 | L24: Municipal | M24: INST. DE PREV. DOS SERVIDORES DE RIACHUELO | T24: 1100 | U24: CLARA KESIA CANDIDO DE MEDEIROS | V24: 5262023436
A25: 002541/2024 | C25: 45608 | D25: 45622 | E25: 45629 | G25: 45814 | H25: 45826 | L25: Municipal | M25: CAMARA MUNICIPAL DE SANTA CRUZ | T25: 10636.98 | U25: CLAUDIO MARQUES DE MACEDO, PREFEITO | V25: 2499945427 | W25: Sem vínculo
A26: 000407/2024 | C26: 45622 | D26: 45625 | E26: 45631 | L26: Municipal | M26: PREFEITURA MUNICIPAL DE CORONEL EZEQUIEL | T26: 29600 | U26: CLAUDIO MARQUES DE MACEDO, PREFEITO | V26: 2499945427 | W26: Abrir APR e seguir com a execução por outros meios
A27: 000850/2025 | B27: SIM | C27: 45821 | D27: 45826 | E27: 45835 | I27: sim | L27: Estadual | M27: SEAD/RN | T27: 30200 | U27: CLEMENCEAU ALVES | V27: 26162180468
A28: 002595/2024 | C28: 45729 | D28: 45736 | E28: 45748 | L28: Municipal | M28: PREFEITURA MUNICIPAL DE RAFAEL GODEIRO | P28: 45785 | Q28: integral | T28: 2800 | U28: Clevilandia Samara de Vasconcelos Belarmino | V28: 8951902498
A29: 004896/2024 | C29: 45727 | D29: 45728 | E29: 45742 | F29: 45811 | L29: Municipal | M29: PREFEITURA MUNICIPAL DE CAIÇARA DO RIO DOS VENTOS | P29: 45810 | Q29: parcelado | T29: 4200 | U29: CONCEICAO DE MARIA GOMES LISBOA ROCHA | V29: 5351429438
A30: 004921/2024 | B30: SIM | C30: 45638 | D30: 45687 | E30: 45693 | F30: 45743 | I30: sim | L30: Municipal | M30: PREFEITURA MUNICIPAL DE NATAL | T30: 5000 | U30: Cristina Diniz Barreto de Paiva | V30: 39242730491
A31: 000876/2025 | C31: 45848 | D31: 45854 | E31: 45866 | F31: 45874 | L31: Municipal | M31: Câmara Municipal de Serra Caiada | P31: 45874 | Q31: parcelado | T31: 3000 | U31: Edilmo Lira | V31: 67287140497
A32: 004903/2024 | B32: SIM | C32: 45727 | D32: 45728 | E32: 45748 | G32: 45826 | H32: 45841 | I32: sim | L32: Municipal | M32: PREFEITURA MUNICIPAL DE EXTREMOZ/EXTREMOZPREV | T32: 15000 | U32: Edinalva Nascimento de Araújo | V32: 48161519404
A33: 000731/2025 | B33: SIM | C33: 45821 | D33: 45826 | E33: 45834 | F33: 45883 | I33: sim | L33: Estadual | M33: ALRN | T33: 6954.15 | U33: Edmilson Targino de Oliveira Bezerra | V33: 28922590459
A34: 002617/2024 | C34: 45643 | D34: 45686 | E34: 45695 | L34: Estadual | M34: IPERN | T34: 9000 | U34: EGIDIO DANTAS DE MEDEIROS FILHO | V34: 8604614400 | W34: Prcesso arquivado. Dívida encaminhada à PGE/RN.
A35: 002057/2024 | C35: 45608 | D35: 45614 | E35: 45629 | L35: Municipal | M35: Câmara Municipal de Tenente Laurentino Cruz | P35: 45810 | Q35: parcelado | T35: 2700 | U35: ELIODELSON BEZERRA DA SILVA | V35: 5855108490
A36: 002570/2024 | C36: 45729 | D36: 45736 | E36: 45747 | G36: 45826 | L36: Municipal | M36: CÂMARA MUNICIPAL DE SERRA NEGRA DO NORTE | P36: 45839 | Q36: parcelado | T36: 5000 | U36: ERALDO ALVES DE ARAÚJO | V36: 93755228491
A37: 002059/2024 | C37: 45608 | D37: 45614 | E37: 45628 | G37: 45810 | H37: 45820 | L37: Municipal | M37: PREFEITURA MUNICIPAL DE SANTANA DO MATOS | T37: 5000 | U37: Erinaldo Florencio Xavier da Costa | V37: 2716115451
A38: 000853/2025 | C38: 45821 | D38: 45826 | E38: 45852 | L38: Municipal | M38: CÂMARA MUNICIPAL DE TAIPU | P38: 45854 | Q38: parcelado | T38: 1000 | U38: ERIVAN PINHEIRO DE LIMA | V38: 1010779478
A39: 000879/2025 | C39: 45846 | D39: 45854 | E39: 45876 | L39: Municipal | M39: PREFEITURA MUNICIPAL DE SERRA DE SÃO BENTO | T39: 10000 | U39: EUCLIDES PINTO FEREIRA NETO | V39: 7726796499
A40: 003411/2024 | C40: 45728 | D40: 45730 | E40: 45748 | G40: 45839 | L40: Municipal | M40: CÂMARA MUNICIPAL DE GUAMARÉ | T40: 1100 | U40: Eudes Miranda da Fonseca | V40: 90455088420
...

Sheet Desconto em Folha Valores
A1: PROCESSO | B1: LOCALIZAÇÃO | C1: CPF | D1: Nº DE PARCELAS | E1: OBSERVAÇÕES | F1: ÓRGÃO | G1: PROCESSO SEI OU OUTROS | H1: CADASTRADO | I1: FINALIZADO | J1: VALOR TOTAL | K1: TRANSF. FRAP | L1: 45627 | M1: 45658 | N1: 45689 | O1: 45717 | P1: 45748 | Q1: 45778 | R1: 45809 | S1: 45839 | T1: 45870 | U1: 45901 | V1: 45931 | W1: 45962 | X1: 45992 | Y1: 46023 | Z1: 46054 | AA1: 46082 | AB1: 46113 | AC1: 46143 | AD1: 46174
A2: 000070/2025 | B2: CCD | C2: 1179288440 | D2: 18 | F2: Prefeitura Municipal de Messias Targino | H2: SIM | J2: 3664.78 | AA2: 209.32 | AB2: 209.32
A3: 000403/2025 | B3: ARQUI | C3: 6975973423 | D3: 1 | F3: PREFEITURA MUNICIPAL DE PILÕES | H3: SIM | I3: sim | J3: 1179.02 | K3: sim | S3: 1179.02
A4: 000407/2025 | B4: CCD | C4: 9008572427 | D4: 6 | F4: PREFEITURA MUNICIPAL DE LAJES | H4: SIM | J4: 2464.08 | Y4: 410.68 | Z4: 410.68 | AA4: 410.68 | AB4: 410.68
A5: 000415/2024 | B5: CCD | C5: 8984449423 | D5: 33 | F5: IPSS - Inst. Prev. SOCIAL Dos Serv Mun. de Olho Dagua Dos Borges | H5: SIM | J5: 6717.34 | L5: 203.56 | M5: 203.56 | N5: 203.56 | O5: 203.56 | Q5: 203.56 | R5: 203.56 | S5: 203.56 | T5: 203.56 | U5: 203.56 | V5: 203.56 | W5: 203.56 | X5: 203.56 | Y5: 203.56 | Z5: 203.56 | AB5: 203.56
A6: 000423/2024 | B6: CCD | C6: 2140437462 | D6: 43 | F6: IPERN / Prefeitura Municipal de Ipueira | G6: 03810015.004516/2025-57 | H6: SIM | J6: 21474.79 | L6: 640 | W6: 500.93 | X6: 500.93 | Y6: 500.93 | Z6: 500.93 | AA6: 500.93 | AB6: 500.93
A7: 000728/2025 | B7: GCGEO | C7: 2567003460 | D7: 5 | F7: Prefeitura Municipal de Tenente Ananias | H7: SIM | I7: sim | J7: 3832.23 | K7: sim | T7: 766.45 | U7: 766.45 | V7: 766.45 | W7: 766.45 | X7: 766.45
A8: 000731/2025 | B8: CCD | C8: 28922590459 | D8: 8 | F8: ALRN | H8: SIM | I8: sim | J8: 10765.66 | S8: 1422.03 | T8: 1422.03 | U8: 1422.03 | V8: 1422.03 | W8: 1422.03 | X8: 1422.03 | Y8: 1422.03 | Z8: 811.48
A9: 000850/2025 | C9: 26162180468 | D9: 74 | F9: SEAD/RN | H9: SIM | J9: 42298.42 | S9: 571.6 | T9: 571.6 | U9: 571.6 | V9: 571.6 | W9: 571.6 | X9: 571.6 | Y9: 571.6 | Z9: 571.6 | AA9: 571.6 | AB9: 571.6
A10: 000859/2025 | B10: CCD | C10: 81327862468 | D10: 21 | F10: Câmara Municipal de Serrinha dos Pintos | H10: SIM | J10: 31992.08 | AA10: 1551.79 | AB10: 1551.79
A11: 000874/2025 | B11: CCD | C11: 9060340434 | D11: 32 | F11: SESAP/RN | H11: SIM | J11: 44890.24 | T11: 1435.88 | U11: 1435.88 | V11: 1435.88 | W11: 1435.88 | X11: 1435.88 | Y11: 1435.88 | Z11: 1435.88 | AA11: 1435.88 | AB11: 1435.88
A12: 001434/2023 | B12: CCD | C12: 789686406 | D12: 55 | F12: Prefeitura Municipal de Triunfo Potiguar | H12: SIM | J12: 56856.07 | U12: 1038.82 | V12: 1038.82 | W12: 1038.82 | X12: 1038.82 | Y12: 1038.82 | Z12: 1038.82 | AA12: 1094.91 | AB12: 1094.91 | AC12: 1094.91
A13: 001454/2023 | B13: CCD | C13: 3465952405 | D13: 7 | F13: SEEC/RN | G13: 00410096.000677/2025-24 | H13: SIM | I13: sim | J13: 6175.3 | N13: 966.72 | O13: 966.72 | P13: 966.72 | Q13: 966.72 | R13: 966.72 | S13: 966.72 | T13: 374.98
A14: 001459/2023 | B14: CCD | C14: 76217663449 | D14: 59 | F14: Prefeitura Municipal de Pedra Preta | H14: SIM | J14: 19845.59 | O14: 338.85 | P14: 338.85 | Q14: 338.85 | R14: 338.85 | S14: 338.85 | T14: 338.85 | U14: 338.85 | V14: 338.85 | W14: 338.85 | X14: 338.85 | Y14: 338.85 | Z14: 338.85 | AA14: 338.85 | AB14: 338.85
A15: 001480/2025 | B15: ARQUI | C15: 6975973423 | D15: 2 | F15: ITEP/RN | H15: SIM | I15: sim | J15: 1200.57 | K15: sim | T15: 600.28 | U15: 600.28
A16: 001484/2025 | B16: CCD | C16: 70198144415 | D16: 12 | F16: Câmara Municipal de Frutuoso Gomes | H16: SIM | J16: 5766.98 | T16: 480.58 | U16: 480.58 | V16: 480.58 | W16: 480.58 | X16: 480.58 | Y16: 480.58 | Z16: 480.58 | AA16: 480.58 | AB16: 480.58
A17: 001486/2025 | B17: CCD | C17: 22983333434 | D17: 59 | F17: IPERN | H17: SIM | J17: 43697.21 | Y17: 751.43 | Z17: 751.43 | AA17: 751.43 | AB17: 751.43
A18: 001492/2025 | B18: CCD | C18: 46524061420 | D18: 9 | F18: IPERN | H18: SIM | J18: 5443.94 | U18: 653.95 | V18: 653.95 | W18: 653.95 | Z18: 653.95 | AA18: 653.95 | AB18: 653.95
A19: 001498/2025 | B19: DE_MANDA | C19: 55215335400 | D19: 10 | F19: Prefeitura Municipal de Santa Maria | H19: SIM | J19: 1884.68 | W19: 188.46 | X19: 188.46 | Y19: 188.46 | Z19: 188.46 | AA19: 188.46 | AB19: 188.46
A20: 001499/2025 | B20: CCD | C20: 4383990487 | D20: 48 | F20: IPERN | H20: SIM | J20: 35480.87 | W20: 745.6 | X20: 745.6 | Y20: 745.6 | Z20: 745.6 | AA20: 745.6 | AB20: 745.6
A21: 001864/2025 | B21: CCD | C21: 12977608400 | D21: 61 | F21: Gabinete Civil do Governador/RN | H21: SIM | J21: 31270.98 | U21: 515.75 | V21: 515.75 | W21: 515.75 | X21: 515.75 | Y21: 515.75 | Z21: 515.75 | AA21: 515.75 | AB21: 515.75
A22: 002012/2025 | B22: GCAED | C22: 59682574404 | D22: 2 | F22: Prefeitura Municipal de Afonso Bezerra | H22: SIM | I22: sim | J22: 5632.35 | K22: sim | U22: 4155.57 | V22: 1476.78
A23: 002013/2025 | B23: CCD | C23: 15706141487 | D23: 12 | F23: SEEC/RN | H23: SIM | J23: 11968.94 | R23: 997.41 | S23: 997.41 | T23: 997.41 | U23: 997.41 | V23: 997.41 | W23: 997.41 | X23: 997.41 | Y23: 997.41 | Z23: 997.41 | AA23: 997.41 | AB23: 997.41
A24: 002019/2025 | B24: GCPOT | C24: 5020735434 | D24: 1 | F24: UFRN | H24: SIM | I24: sim | J24: 1038.76 | V24: 1038.76
A25: 002027/2024 | B25: CCD | C25: 1075318440 | D25: 30 | F25: SESAP/RN | H25: SIM | J25: 28601.96 | N25: 953.4 | O25: 953.4 | P25: 953.4 | Q25: 953.4 | R25: 953.4 | S25: 953.4 | T25: 953.4 | U25: 953.4 | V25: 953.4 | W25: 953.4 | X25: 953.4 | Y25: 953.4 | Z25: 953.4 | AA25: 953.4 | AB25: 953.4
A26: 002031/2024 | B26: DE_EXP | C26: 50149806434 | D26: 96 | F26: SEEC/RN | H26: SIM | J26: 55475.46 | P26: 577.86 | Q26: 577.86 | R26: 577.86 | S26: 577.86 | T26: 577.86 | U26: 577.86 | V26: 577.86 | W26: 577.86 | X26: 577.86 | Y26: 577.86 | Z26: 577.86 | AA26: 577.86 | AB26: 577.86
A27: 002157/2025 | B27: CCD | C27: 50104411449 | D27: 11 | F27: ALRN | H27: SIM | J27: 4556.05 | V27: 444.01 | W27: 444.01 | X27: 444.01 | Y27: 444.01 | Z27: 444.01 | AA27: 444.01 | AB27: 444.01
A28: 002392/2025 | B28: CCD | C28: 6432232406 | D28: 46 | F28: Prefeitura Municipal de Serra de São Bento | H28: SIM | J28: 6897.45 | W28: 150 | X28: 150 | Y28: 150 | Z28: 150 | AB28: 150
A29: 002400/2025 | B29: ARQUI | C29: 53838033434 | D29: 1 | F29: PREFEITURA MUNICIPAL DE PILÕES | I29: sim | J29: 2115.48 | K29: sim | U29: 2115.48
A30: 002401/2025 | B30: DE_EXP | C30: 85248290449 | D30: 1 | F30: PREFEITURA MUNICIPAL DE GUAMARÉ | I30: sim | J30: 294.02 | U30: 294.02
A31: 002406/2025 | B31: CCD | C31: 37824023400 | D31: 15 | F31: IPERN | H31: SIM | J31: 14883.62 | W31: 1034.2 | X31: 1034.2 | Y31: 1034.2 | Z31: 1034.2 | AA31: 1034.2 | AB31: 1034.2
A32: 002571/2024 | B32: GCAED | C32: 2445986494 | D32: 1 | F32: Prefeitura Municipal de Lajes Pintada | H32: SIM | I32: sim | J32: 2521.43 | K32: sim | U32: 2521.43
A33: 002604/2024 | B33: CCD | C33: 1179288440 | D33: 36 | F33: Prefeitura Municipal de Messias Targino | H33: SIM | J33: 36097.73 | AA33: 1002.71 | AB33: 1002.71
A34: 002611/2024 | B34: ARQUI | C34: 13070231420 | D34: 40 | E34: Nulidade da certidão de trânsito em julgado. Cancelamento do desconto em folha. | J34: 62601.71 | N34: 1565.04
A35: 002612/2025 | B35: CCD | C35: 83749837449 | D35: 86 | F35: SEAD/RN | H35: SIM | J35: 38510.37 | W35: 450.92 | X35: 450.92 | Y35: 450.92 | Z35: 450.92 | AA35: 450.92 | AB35: 450.92
A36: 002725/2025 | B36: CCD | C36: 42362385787 | D36: 2 | F36: IPERN | H36: SIM | I36: sim | J36: 4431.15 | Z36: 2042.67 | AA36: 2388.48
A37: 002725/2025 | B37: CCD | C37: 26162180468 | D37: 38 | F37: SEAD/RN | H37: SIM | J37: 8243.4 | AA37: 221.63 | AB37: 221.63
A38: 002740/2025 | B38: CCD | C38: 10811932478 | D38: 33 | F38: Prefeitura Municipal de Areia Branca | H38: SIM | J38: 47085.69 | AB38: 1428.96
A39: 002819/2025 | B39: CCD | C39: 46554408487 | D39: 26 | F39: SECRETARIA DE ESTADO DA TRIBUTAÇÃO | H39: SIM | J39: 16624.87 | Y39: 515.61 | Z39: 644.37 | AA39: 644.37 | AB39: 644.37
A40: 002820/2025 | B40: CCD | C40: 15706141487 | D40: 9 | F40: SEEC/RN | H40: SIM | J40: 11308.99 | Z40: 1316.88 | AA40: 1316.88 | AB40: 1316.88
...

Sheet Processos Antigos
A1: PROCESSO | B1: DESPACHO | C1: NOTIFICAÇÃO | D1: RECEBIMENTO AR | E1: RESPOSTA | F1: 2 NOTIFICAÇÃO | G1: RECEBIMENTO AR 2 NOT | H1: Desc. Folha | I1: ESTADUAL / MUNICIPAL | J1: ÓRGÃO | K1: PROCESSO SEI | L1: TRASNF. FRAP | M1: PAGO SITE TCE | N1: TIPO PAGAMENTO | O1: REMANESCENTE | P1: APR | Q1: VALOR ORIGINAL | R1: NOME | S1: CPF | T1: OBSERVAÇÕES
A2: 012970/2017 | B2: 42965 | C2: 42965 | D2: 42972 | E2: 42975 | H2: sim | I2: Estadual | J2: IPERN | L2: sim | Q2: 500 | R2: Maria das Graças Fernandes Costa da Motta | S2: 87677830404
A3: 701107/2012 | B3: 42962 | H3: sim | I3: Estadual | J3: SESAP/RN | L3: sim | Q3: 1680 | R3: Josiano Ribeiro Bilro da Silva | S3: 50288890400
A4: 015786/2016 | C4: 42836 | D4: 42909 | E4: 42928 | H4: sim | I4: Estadual | J4: SESAP/RN | Q4: 500 | R4: José Júlio Fernandes Neto | S4: 59668784472
A5: 021694/2016 | B5: 42905 | C5: 42909 | D5: 42916 | E5: 42929 | H5: sim | I5: Estadual | J5: SEEC/RN
A6: 700985/2012 | H6: sim | I6: Estadual | J6: Gabinete Civil do Governador | K6: 00110013.000360/2018-06 | Q6: 27448 | R6: Jose de Arimateia Braz | S6: 12977608400
A7: 005303/2017 | B7: 42843 | C7: 42900 | D7: 42913 | E7: 42947 | H7: sim | I7: Estadual | J7: ALRN | R7: Wanira de Holanda Brasil | S7: 75128799468
A8: 005352/2017 | B8: 42894 | C8: 42900 | D8: 42909 | E8: 42928 | H8: sim | I8: Estadual | J8: SESAP/RN | Q8: 5730 | R8: Maria da Guia Dantas Araújo | S8: 87519607453
A9: 021661/2016 | B9: 42895 | C9: 42905 | D9: 42908 | E9: 42929 | H9: sim | I9: Estadual | J9: SEEC/RN | K9: 00110013.007447/2019-87 | Q9: 22500 | R9: Tertúlio Alves da Silva | S9: 63841746420
A10: 021690/2016 | B10: 42937 | C10: 42937 | D10: 42943 | E10: 42962 | H10: sim | I10: Estadual | J10: SEEC/RN | K10: 00110013.007756/2019-57 | Q10: 12900 | R10: JAILTON JOSÉ XAVIER DE LIMA | S10: 56565925453

Sheet Monitoramento NEREU
A1: número processo | B1: ano processo | C1: VALOR IMPLEMENTADO | D1: DATA IMPLEMENTAÇÃO | E1: Colunas1 | F1: Processo SEI | G1: Relator | H1: OBS | I1: Desconto verificado no SIAIDP | J1: Desconto verificado no FRAP
A2: 3661 | B2: 2022 | C2: 1292.41 | D2: 45658 | E2: =C2+C1 -> #VALUE! | F2: 0110012.003143/2024-18 | G2: CARLOS THOMPSON COSTA FERNANDES | H2: somada à multa do processo 3269/2023 para implementação | I2: OK | J2: OK (Documento 202.501.310.027.938 do extrato de 02/2025 da conta 700000-6)
A3: 3269 | B3: 2023 | C3: 1235.29 | D3: 45658 | F3: 00110012.003144/2024-62 | G3: CARLOS THOMPSON COSTA FERNANDES | H3: somada à multa do processo 3661/2022 para implementação | I3: OK | J3: OK (Documento 202.501.310.027.938 do extrato de 02/2025 da conta 700000-6)
A4: 1391 | B4: 2023 | C4: 1246.59 | D4: 45689 | F4: 0110012.003135/2024-71 | G4: CARLOS THOMPSON COSTA FERNANDES | H4: somada à multa do processo 1418/2023 para implementação | I4: OK | J4: OK (Documento 202.502.280.064.161 do extrato de 03/2025 da conta 700000-6)
A5: 1418 | B5: 2023 | C5: 1213.76 | D5: 45689 | E5: =C5+C4 -> 2460.35 | F5: 110012.003138/2024-13 | G5: CARLOS THOMPSON COSTA FERNANDES | H5: somada à multa do processo 1391/2023 para implementação | I5: OK | J5: OK (Documento 202.502.280.064.161 do extrato de 03/2025 da conta 700000-6)
A6: 3666 | B6: 2022 | C6: 1281.37 | D6: 45717 | F6: 0110012.003140/2024-84 | G6: CARLOS THOMPSON COSTA FERNANDES | H6: somada à multa do processo 99/2023 para implementação | I6: OK | J6: OK (Documento 202.504.010.028.737 do extrato de 04/2025 da conta 700000-6)
A7: 99 | B7: 2023 | C7: 1225.15 | D7: 45717 | F7: 110012.003139/2024-50 | G7: CARLOS THOMPSON COSTA FERNANDES | H7: somada à multa do processo 3666/2022 para implementação | I7: OK | J7: OK (Documento 202.504.010.028.737 do extrato de 04/2025 da conta 700000-6)
A8: 1417 | B8: 2023 | C8: 1213.76 | D8: 45748 | F8: 110012.003137/2024-61 | G8: CARLOS THOMPSON COSTA FERNANDES | H8: somada à multa do processo 1420/2023 para implementação | I8: OK | J8: OK (Documento 202.505.060.035.364 do extrato de 05/2025 da conta 700000-6)
A9: 1420 | B9: 2023 | C9: 1249.47 | D9: 45748 | F9: 0110012.003141/2024-29 | G9: CARLOS THOMPSON COSTA FERNANDES | H9: somada à multa do processo 1417/2023 para implementação | I9: OK | J9: OK (Documento 202.505.060.035.364 do extrato de 05/2025 da conta 700000-6)
A10: 100 | B10: 2023 | C10: 1225.15 | D10: 45778 | F10: 0110012.003142/2024-73 | G10: CARLOS THOMPSON COSTA FERNANDES | H10: somada à multa do processo 106/2023 para implementação | I10: OK | J10: OK (Documento 202.506.040.011.394 do extrato de 06/2025 da conta 700000-6)
A11: 106 | B11: 2023 | C11: 1252.2 | D11: 45778 | F11: 110012.003261/2024-26 | G11: CARLOS THOMPSON COSTA FERNANDES | H11: somada à multa do processo 100/2023 para implementação | I11: OK | J11: OK (Documento 202.506.040.011.394 do extrato de 06/2025 da conta 700000-6)
A12: 1421 | B12: 2023 | C12: 1262.34 | D12: 45809 | F12: 00110012.003300/2024-95 | G12: CARLOS THOMPSON COSTA FERNANDES | H12: somada à multa do processo 1423/2023 para implementação
A13: 1423 | B13: 2023 | C13: 1257.4 | D13: 45809 | F13: 110012.003277/2024-39 | G13: CARLOS THOMPSON COSTA FERNANDES | H13: somada à multa do processo 1421/2023 para implementação
A14: 3077 | B14: 2022 | C14: 1302.79 | D14: 45839 | F14: 110012.003280/2024-52 | G14: CARLOS THOMPSON COSTA FERNANDES | H14: somada à multa do processo 1446/2023 para implementação
A15: 1446 | B15: 2023 | C15: 1205.19 | D15: 45839 | F15: 0110012.003278/2024-83 | G15: CARLOS THOMPSON COSTA FERNANDES | H15: somada à multa do processo 3077/2022 para implementação
A16: 98 | B16: 2023 | C16: 1281.37 | D16: 45870 | F16: 110012.003287/2024-74 | G16: CARLOS THOMPSON COSTA FERNANDES | H16: somada à multa do processo 3412/2024 para implementação
A17: 3412 | B17: 2024 | C17: 1118.97 | D17: 45870 | F17: 110012.003301/2024-30 | G17: CARLOS THOMPSON COSTA FERNANDES | H17: somada à multa do processo 98/2023 para implementação
A18: 117 | B18: 2023 | C18: 1257.4 | D18: 45901 | F18: 0110012.003268/2024-48 | G18: CARLOS THOMPSON COSTA FERNANDES | H18: somada à multa do processo 131/2023 para implementação
A19: 131 | B19: 2023 | C19: 1281.37 | D19: 45901 | F19: 00110012.003267/2024-01 | G19: CARLOS THOMPSON COSTA FERNANDES | H19: somada à multa do processo 117/2023 para implementação
A20: 118 | B20: 2023 | C20: 1257.4 | D20: 45931 | F20: 0110012.003266/2024-59 | G20: CARLOS THOMPSON COSTA FERNANDES | H20: somada à multa do processo 120/2023 para implementação
A21: 120 | B21: 2023 | C21: 1281.37 | D21: 45931 | F21: 00110012.003265/2024-12 | G21: CARLOS THOMPSON COSTA FERNANDES | H21: somada à multa do processo 118/2023 para implementação
A22: 107 | B22: 2023 | C22: 1281.37 | D22: 45962 | F22: 110012.003263/2024-15 | G22: CARLOS THOMPSON COSTA FERNANDES | H22: somada à multa do processo 130/2023 para implementação
A23: 130 | B23: 2023 | C23: 1284.97 | D23: 45962 | F23: 00110012.003264/2024-60 | G23: ANTONIO GILBERTO DE OLIVEIRA JALES | H23: somada à multa do processo 107/2023 para implementação
... A43: 3074 | B43: 2022 | C43: 1315.17 | D43: 46266 | F43: 0110012.003275/2024-40 | G43: CARLOS THOMPSON COSTA FERNANDES | H43: somada à multa do processo 3073/2022 para implementação
A44: 2718 | B44: 2022 | G44: ANA PAULA DE OLIVEIRA GOMES | H44: ainda não teve retorno da notificação
C45: =SUM(C2:C44) -> 52933.99

Sheet D. F. Valores Proc. Antigos
A1: PROCESSO | B1: CPF | C1: Nº DE PARCELAS | D1: OBSERVAÇÕES | E1: CADASTRADO | F1: VALOR TOTAL | G1: TRANSF. FRAP | H1: 42917 | I1: 42948 | J1: 42979 | K1: 43009 | L1: 43040 | M1: 43070 | N1: 43101 | O1: 43132 | P1: 43160 | Q1: 43191 | R1: 43221 | S1: 43252 | T1: 43282 | U1: 43313 | V1: 43344 | W1: 43374 | X1: 43405 | Y1: 43435 | Z1: 43709 | AA1: 43739 | AB1: 45627 | AC1: 45658 | AD1: 45689 | AE1: 45717 | AF1: 45748 | AG1: 45778 | AH1: 45809 | AI1: 45839 | AJ1: 45870 | AK1: 45901 | AL1: 45931 | AM1: 45962 | AN1: 45992 | AO1: 46023 | AP1: 46054 | AQ1: 46082 | AR1: 46113
A2: 012970/2017 | B2: 87677830404 | C2: 2 | F2: 512.06 | G2: sim | K2: 229.62 | L2: 282.44
A3: 701107/2012 | B3: 50288890400 | C3: 2 | F3: 1760.02 | G3: sim | Z3: 880.01 | AA3: 880.01
A4: 015786/2016 | B4: 59668784472 | C4: 1 | F4: 523.53 | I4: 523.53
A5: 021694/2016 | C5: 17 | F5: 6105.56
A6: 700985/2012 | B6: 12977608400 | C6: 252 | I6: 121.81
A7: 005303/2017 | B7: 75128799468 | C7: 187 | D7: Multa percentual + ressarcimento | F7: 188241.92 | H7: 1011.87 | I7: 1011.87 | J7: 1011.87 | K7: 1006.59 | L7: 1006.59 | M7: 1006.59 | N7: 1006.59 | O7: 1006.59 | P7: 1006.59 | Q7: 1006.59 | R7: 1006.59 | S7: 1006.59 | T7: 1006.59 | U7: 1006.59 | V7: 1006.59 | W7: 1006.59 | X7: 1006.59 | Y7: 1006.59
A8: 005352/2017 | B8: 87519607453 | I8: 536.67 | J8: 536.67 | K8: 536.67 | L8: 536.67 | M8: 536.67 | N8: 536.67 | O8: 536.67 | P8: 536.67 | Q8: 536.67 | R8: 536.67 | S8: 473
A9: 021661/2016 | B9: 63841746420 | C9: 77 | E9: SIM | F9: 24689.98 | I9: 322.8
A10: 021690/2016 | B10: 56565925453 | C10: 125 | F10: 15220.34 | J10: 121.81

Sheet RESUMO
A2: TOTAL DE NOTIFICAÇÕES | B2: ='Monitoramento Geral'!D240 -> 232
A3: RESPOSTAS RECEBIDAS | B3: ='Monitoramento Geral'!F240 -> 66
A4: DESCONTOS IMPLEMENTADOS | B4: ='Monitoramento Geral'!I240 -> 77
A5: TRANS. FRAP COMPROVADA | B5: ='Monitoramento Geral'!O240 -> 13
A6: PAGAMENTO NO SITE | B6: ='Monitoramento Geral'!P240 -> 40
A7: SEM RESPOSTA/RETORNO
